Workbook

Sheet Data
A1: Order ID | B1: Order Date | C1: Year | D1: Month | E1: Region | F1: State | G1: City | H1: Dealership | I1: Model | J1: Category | K1: Fuel Type | L1: Quantity | M1: Sales (₹) | N1: COGS (₹) | O1: Profit (₹) | P1: Payment Method
A2: KIA-25-0001 | B2: 45659 | C2: =YEAR(B2) -> 2025 | D2: =CHOOSE(MONTH(B2),"Jan","Feb","Mar","Apr","May","Jun","Jul","Aug","Sep","Oct","Nov","Dec") -> Jan | E2: West | F2: Maharashtra | G2: Mumbai | H2: Mumbai Thane | I2: Clavis EV | J2: Premium & EV | K2: Electric | L2: 1 | M2: 1913000 | N2: 1672000 | O2: =M2-N2 -> 241000 | P2: UPI
A3: KIA-25-0002 | B3: 45659 | C3: =YEAR(B3) -> 2025 | D3: =CHOOSE(MONTH(B3),"Jan","Feb","Mar","Apr","May","Jun","Jul","Aug","Sep","Oct","Nov","Dec") -> Jan | E3: South | F3: Karnataka | G3: Bengaluru | H3: Bengaluru Whitefield | I3: Carens Clavis EV | J3: Premium & EV | K3: Electric | L3: 1 | M3: 1803000 | N3: 1443900 | O3: =M3-N3 -> 359100 | P3: Bank Finance
A4: KIA-25-0003 | B4: 45661 | C4: =YEAR(B4) -> 2025 | D4: =CHOOSE(MONTH(B4),"Jan","Feb","Mar","Apr","May","Jun","Jul","Aug","Sep","Oct","Nov","Dec") -> Jan | E4: North | F4: Delhi | G4: Delhi | H4: Delhi Okhla | I4: EV9 | J4: Premium & EV | K4: Electric | L4: 1 | M4: 12939000 | N4: 10359300 | O4: =M4-N4 -> 2579700 | P4: Credit Card
A5: KIA-25-0004 | B5: 45661 | C5: =YEAR(B5) -> 2025 | D5: =CHOOSE(MONTH(B5),"Jan","Feb","Mar","Apr","May","Jun","Jul","Aug","Sep","Oct","Nov","Dec") -> Jan | E5: South | F5: Karnataka | G5: Bengaluru | H5: Bengaluru Koramangala | I5: Seltos GTX | J5: Mid-size SUV | K5: Diesel | L5: 1 | M5: 1683000 | N5: 1391000 | O5: =M5-N5 -> 292000 | P5: Bank Finance
A6: KIA-25-0005 | B6: 45664 | C6: =YEAR(B6) -> 2025 | D6: =CHOOSE(MONTH(B6),"Jan","Feb","Mar","Apr","May","Jun","Jul","Aug","Sep","Oct","Nov","Dec") -> Jan | E6: East | F6: West Bengal | G6: Kolkata | H6: Kolkata Salt Lake | I6: Sonet GTX | J6: Compact SUV | K6: Diesel | L6: 1 | M6: 1283000 | N6: 1036500 | O6: =M6-N6 -> 246500 | P6: Credit Card
A7: KIA-25-0006 | B7: 45666 | C7: =YEAR(B7) -> 2025 | D7: =CHOOSE(MONTH(B7),"Jan","Feb","Mar","Apr","May","Jun","Jul","Aug","Sep","Oct","Nov","Dec") -> Jan | E7: West | F7: Gujarat | G7: Ahmedabad | H7: Ahmedabad Satellite | I7: Carens Clavis EV | J7: Premium & EV | K7: Electric | L7: 1 | M7: 1788000 | N7: 1536400 | O7: =M7-N7 -> 251600 | P7: Net Banking
A8: KIA-25-0007 | B8: 45668 | C8: =YEAR(B8) -> 2025 | D8: =CHOOSE(MONTH(B8),"Jan","Feb","Mar","Apr","May","Jun","Jul","Aug","Sep","Oct","Nov","Dec") -> Jan | E8: South | F8: Karnataka | G8: Bengaluru | H8: Bengaluru Whitefield | I8: Carens Clavis | J8: MPV | K8: Petrol | L8: 1 | M8: 1244000 | N8: 1026300 | O8: =M8-N8 -> 217700 | P8: UPI
A9: KIA-25-0008 | B9: 45669 | C9: =YEAR(B9) -> 2025 | D9: =CHOOSE(MONTH(B9),"Jan","Feb","Mar","Apr","May","Jun","Jul","Aug","Sep","Oct","Nov","Dec") -> Jan | E9: West | F9: Maharashtra | G9: Pune | H9: Pune Hinjewadi | I9: Carens Clavis | J9: MPV | K9: Petrol | L9: 1 | M9: 1251000 | N9: 1068500 | O9: =M9-N9 -> 182500 | P9: Bank Finance
A10: KIA-25-0009 | B10: 45671 | C10: =YEAR(B10) -> 2025 | D10: =CHOOSE(MONTH(B10),"Jan","Feb","Mar","Apr","May","Jun","Jul","Aug","Sep","Oct","Nov","Dec") -> Jan | E10: West | F10: Maharashtra | G10: Mumbai | H10: Mumbai Thane | I10: Seltos HTX | J10: Mid-size SUV | K10: Petrol | L10: 1 | M10: 1360000 | N10: 1135400 | O10: =M10-N10 -> 224600 | P10: Bank Finance
A11: KIA-25-0010 | B11: 45672 | C11: =YEAR(B11) -> 2025 | D11: =CHOOSE(MONTH(B11),"Jan","Feb","Mar","Apr","May","Jun","Jul","Aug","Sep","Oct","Nov","Dec") -> Jan | E11: South | F11: Tamil Nadu | G11: Chennai | H11: Chennai OMR | I11: Sonet HTX | J11: Compact SUV | K11: Petrol | L11: 1 | M11: 930000 | N11: 816900 | O11: =M11-N11 -> 113100 | P11: UPI
A12: KIA-25-0011 | B12: 45672 | C12: =YEAR(B12) -> 2025 | D12: =CHOOSE(MONTH(B12),"Jan","Feb","Mar","Apr","May","Jun","Jul","Aug","Sep","Oct","Nov","Dec") -> Jan | E12: West | F12: Gujarat | G12: Ahmedabad | H12: Ahmedabad SG Highway | I12: Syros HTK | J12: Compact SUV | K12: Petrol | L12: 1 | M12: 991000 | N12: 832000 | O12: =M12-N12 -> 159000 | P12: Debit Card
A13: KIA-25-0012 | B13: 45673 | C13: =YEAR(B13) -> 2025 | D13: =CHOOSE(MONTH(B13),"Jan","Feb","Mar","Apr","May","Jun","Jul","Aug","Sep","Oct","Nov","Dec") -> Jan | E13: West | F13: Maharashtra | G13: Mumbai | H13: Mumbai Andheri | I13: Seltos GTX | J13: Mid-size SUV | K13: Diesel | L13: 1 | M13: 1743000 | N13: 1411500 | O13: =M13-N13 -> 331500 | P13: Credit Card
... A1011: KIA-26-1010 | B1011: 46319 | C1011: =YEAR(B1011) -> 2026 | D1011: =CHOOSE(MONTH(B1011),"Jan","Feb","Mar","Apr","May","Jun","Jul","Aug","Sep","Oct","Nov","Dec") -> Oct | E1011: West | F1011: Gujarat | G1011: Ahmedabad | H1011: Ahmedabad SG Highway | I1011: Seltos HTX | J1011: Mid-size SUV | K1011: Petrol | L1011: 1 | M1011: 1335000 | N1011: 1091600 | O1011: =M1011-N1011 -> 243400 | P1011: UPI

Sheet pivot_table
A1: Month filter (from Dashboard) | B1: =IF(Dashboard!$V$6="All","*",Dashboard!$V$6) -> * | D1: Total Sales (₹ Cr) | E1: =SUMIFS(Data!$M$2:$M$5000,Data!$D$2:$D$5000,$B$1,Data!$E$2:$E$5000,$B$2)/10^7 -> 162.3258
A2: Region filter (from Dashboard) | B2: =IF(Dashboard!$V$21="All","*",Dashboard!$V$21) -> * | D2: Total Profit (₹ Cr) | E2: =SUMIFS(Data!$O$2:$O$5000,Data!$D$2:$D$5000,$B$1,Data!$E$2:$E$5000,$B$2)/10^7 -> 26.05413
A3: All tables below follow these two filters. Values are in ₹ Crore. | D3: Total COGS (₹ Cr) | E3: =SUMIFS(Data!$N$2:$N$5000,Data!$D$2:$D$5000,$B$1,Data!$E$2:$E$5000,$B$2)/10^7 -> 136.27167
D4: Total Orders | E4: =COUNTIFS(Data!$D$2:$D$5000,$B$1,Data!$E$2:$E$5000,$B$2) -> 1010
A6: Sales by Region & Year (₹ Cr) | E6: Orders by Region
A7: Region | B7: 2025 | C7: 2026 | E7: Region | F7: Orders
A8: North | B8: =SUMIFS(Data!$M$2:$M$5000,Data!$D$2:$D$5000,$B$1,Data!$E$2:$E$5000,$B$2,Data!$E$2:$E$5000,$A8,Data!$C$2:$C$5000,B$7)/10^7 -> 16.2592 | C8: =SUMIFS(Data!$M$2:$M$5000,Data!$D$2:$D$5000,$B$1,Data!$E$2:$E$5000,$B$2,Data!$E$2:$E$5000,$A8,Data!$C$2:$C$5000,C$7)/10^7 -> 21.1287 | E8: North | F8: =COUNTIFS(Data!$D$2:$D$5000,$B$1,Data!$E$2:$E$5000,$B$2,Data!$E$2:$E$5000,$E8) -> 222
A9: South | B9: =SUMIFS(Data!$M$2:$M$5000,Data!$D$2:$D$5000,$B$1,Data!$E$2:$E$5000,$B$2,Data!$E$2:$E$5000,$A9,Data!$C$2:$C$5000,B$7)/10^7 -> 17.5985 | C9: =SUMIFS(Data!$M$2:$M$5000,Data!$D$2:$D$5000,$B$1,Data!$E$2:$E$5000,$B$2,Data!$E$2:$E$5000,$A9,Data!$C$2:$C$5000,C$7)/10^7 -> 25.5386 | E9: South | F9: =COUNTIFS(Data!$D$2:$D$5000,$B$1,Data!$E$2:$E$5000,$B$2,Data!$E$2:$E$5000,$E9) -> 276
A10: East | B10: =SUMIFS(Data!$M$2:$M$5000,Data!$D$2:$D$5000,$B$1,Data!$E$2:$E$5000,$B$2,Data!$E$2:$E$5000,$A10,Data!$C$2:$C$5000,B$7)/10^7 -> 3.0698 | C10: =SUMIFS(Data!$M$2:$M$5000,Data!$D$2:$D$5000,$B$1,Data!$E$2:$E$5000,$B$2,Data!$E$2:$E$5000,$A10,Data!$C$2:$C$5000,C$7)/10^7 -> 7.6811 | E10: East | F10: =COUNTIFS(Data!$D$2:$D$5000,$B$1,Data!$E$2:$E$5000,$B$2,Data!$E$2:$E$5000,$E10) -> 70
A11: West | B11: =SUMIFS(Data!$M$2:$M$5000,Data!$D$2:$D$5000,$B$1,Data!$E$2:$E$5000,$B$2,Data!$E$2:$E$5000,$A11,Data!$C$2:$C$5000,B$7)/10^7 -> 34.2377 | C11: =SUMIFS(Data!$M$2:$M$5000,Data!$D$2:$D$5000,$B$1,Data!$E$2:$E$5000,$B$2,Data!$E$2:$E$5000,$A11,Data!$C$2:$C$5000,C$7)/10^7 -> 36.8122 | E11: West | F11: =COUNTIFS(Data!$D$2:$D$5000,$B$1,Data!$E$2:$E$5000,$B$2,Data!$E$2:$E$5000,$E11) -> 442
A14: Sales by Category & Year (₹ Cr)
A15: Category | B15: 2025 | C15: 2026
A16: Compact SUV | B16: =SUMIFS(Data!$M$2:$M$5000,Data!$D$2:$D$5000,$B$1,Data!$E$2:$E$5000,$B$2,Data!$J$2:$J$5000,$A16,Data!$C$2:$C$5000,B$15)/10^7 -> 20.3117 | C16: =SUMIFS(Data!$M$2:$M$5000,Data!$D$2:$D$5000,$B$1,Data!$E$2:$E$5000,$B$2,Data!$J$2:$J$5000,$A16,Data!$C$2:$C$5000,C$15)/10^7 -> 20.9891
A17: Mid-size SUV | B17: =SUMIFS(Data!$M$2:$M$5000,Data!$D$2:$D$5000,$B$1,Data!$E$2:$E$5000,$B$2,Data!$J$2:$J$5000,$A17,Data!$C$2:$C$5000,B$15)/10^7 -> 16.2303 | C17: =SUMIFS(Data!$M$2:$M$5000,Data!$D$2:$D$5000,$B$1,Data!$E$2:$E$5000,$B$2,Data!$J$2:$J$5000,$A17,Data!$C$2:$C$5000,C$15)/10^7 -> 20.929
A18: MPV | B18: =SUMIFS(Data!$M$2:$M$5000,Data!$D$2:$D$5000,$B$1,Data!$E$2:$E$5000,$B$2,Data!$J$2:$J$5000,$A18,Data!$C$2:$C$5000,B$15)/10^7 -> 15.4114 | C18: =SUMIFS(Data!$M$2:$M$5000,Data!$D$2:$D$5000,$B$1,Data!$E$2:$E$5000,$B$2,Data!$J$2:$J$5000,$A18,Data!$C$2:$C$5000,C$15)/10^7 -> 19.1575
A19: Premium & EV | B19: =SUMIFS(Data!$M$2:$M$5000,Data!$D$2:$D$5000,$B$1,Data!$E$2:$E$5000,$B$2,Data!$J$2:$J$5000,$A19,Data!$C$2:$C$5000,B$15)/10^7 -> 19.2118 | C19: =SUMIFS(Data!$M$2:$M$5000,Data!$D$2:$D$5000,$B$1,Data!$E$2:$E$5000,$B$2,Data!$J$2:$J$5000,$A19,Data!$C$2:$C$5000,C$15)/10^7 -> 30.085
A22: Sales by Model (₹ Cr) | D22: Top 5 models
A23: Model | B23: Sales | D23: Rank | E23: Model | F23: Sales (₹ Cr)
A24: Sonet HTX | B24: =SUMIFS(Data!$M$2:$M$5000,Data!$D$2:$D$5000,$B$1,Data!$E$2:$E$5000,$B$2,Data!$I$2:$I$5000,$A24)/10^7 -> 15.9547 | D24: 1 | E24: =INDEX($A$24:$A$35,MATCH(F24,$B$24:$B$35,0)) -> Seltos HTX | F24: =LARGE($B$24:$B$35,$D24) -> 19.0557
A25: Sonet GTX | B25: =SUMIFS(Data!$M$2:$M$5000,Data!$D$2:$D$5000,$B$1,Data!$E$2:$E$5000,$B$2,Data!$I$2:$I$5000,$A25)/10^7 -> 12.1236 | D25: 2 | E25: =INDEX($A$24:$A$35,MATCH(F25,$B$24:$B$35,0)) -> Seltos GTX | F25: =LARGE($B$24:$B$35,$D25) -> 18.1036
A26: Syros HTK | B26: =SUMIFS(Data!$M$2:$M$5000,Data!$D$2:$D$5000,$B$1,Data!$E$2:$E$5000,$B$2,Data!$I$2:$I$5000,$A26)/10^7 -> 13.2225 | D26: 3 | E26: =INDEX($A$24:$A$35,MATCH(F26,$B$24:$B$35,0)) -> Carens Clavis | F26: =LARGE($B$24:$B$35,$D26) -> 17.2979
A27: Seltos HTX | B27: =SUMIFS(Data!$M$2:$M$5000,Data!$D$2:$D$5000,$B$1,Data!$E$2:$E$5000,$B$2,Data!$I$2:$I$5000,$A27)/10^7 -> 19.0557 | D27: 4 | E27: =INDEX($A$24:$A$35,MATCH(F27,$B$24:$B$35,0)) -> Carens Luxury | F27: =LARGE($B$24:$B$35,$D27) -> 17.271
A28: Seltos GTX | B28: =SUMIFS(Data!$M$2:$M$5000,Data!$D$2:$D$5000,$B$1,Data!$E$2:$E$5000,$B$2,Data!$I$2:$I$5000,$A28)/10^7 -> 18.1036 | D28: 5 | E28: =INDEX($A$24:$A$35,MATCH(F28,$B$24:$B$35,0)) -> Sonet HTX | F28: =LARGE($B$24:$B$35,$D28) -> 15.9547
A29: Carens Luxury | B29: =SUMIFS(Data!$M$2:$M$5000,Data!$D$2:$D$5000,$B$1,Data!$E$2:$E$5000,$B$2,Data!$I$2:$I$5000,$A29)/10^7 -> 17.271
A30: Carens Clavis | B30: =SUMIFS(Data!$M$2:$M$5000,Data!$D$2:$D$5000,$B$1,Data!$E$2:$E$5000,$B$2,Data!$I$2:$I$5000,$A30)/10^7 -> 17.2979
A31: Carnival Limousine | B31: =SUMIFS(Data!$M$2:$M$5000,Data!$D$2:$D$5000,$B$1,Data!$E$2:$E$5000,$B$2,Data!$I$2:$I$5000,$A31)/10^7 -> 14.4972
A32: EV6 GT-Line | B32: =SUMIFS(Data!$M$2:$M$5000,Data!$D$2:$D$5000,$B$1,Data!$E$2:$E$5000,$B$2,Data!$I$2:$I$5000,$A32)/10^7 -> 5.8818
A33: EV9 | B33: =SUMIFS(Data!$M$2:$M$5000,Data!$D$2:$D$5000,$B$1,Data!$E$2:$E$5000,$B$2,Data!$I$2:$I$5000,$A33)/10^7 -> 9.0488
A34: Clavis EV | B34: =SUMIFS(Data!$M$2:$M$5000,Data!$D$2:$D$5000,$B$1,Data!$E$2:$E$5000,$B$2,Data!$I$2:$I$5000,$A34)/10^7 -> 10.0015
A35: Carens Clavis EV | B35: =SUMIFS(Data!$M$2:$M$5000,Data!$D$2:$D$5000,$B$1,Data!$E$2:$E$5000,$B$2,Data!$I$2:$I$5000,$A35)/10^7 -> 9.8675
A38: Sales by Month & Year (₹ Cr) | E38: raw values
A39: Month | B39: 2025 | C39: 2026 | E39: 2025 | F39: 2026
A40: Jan | B40: =IF(E40=0,NA(),E40) -> 5.9588 | C40: =IF(F40=0,NA(),F40) -> 5.898 | E40: =SUMIFS(Data!$M$2:$M$5000,Data!$D$2:$D$5000,$B$1,Data!$E$2:$E$5000,$B$2,Data!$D$2:$D$5000,$A40,Data!$C$2:$C$5000,E$39)/10^7 -> 5.9588 | F40: =SUMIFS(Data!$M$2:$M$5000,Data!$D$2:$D$5000,$B$1,Data!$E$2:$E$5000,$B$2,Data!$D$2:$D$5000,$A40,Data!$C$2:$C$5000,F$39)/10^7 -> 5.898
A41: Feb | B41: =IF(E41=0,NA(),E41) -> 3.0921 | C41: =IF(F41=0,NA(),F41) -> 9.6693 | E41: =SUMIFS(Data!$M$2:$M$5000,Data!$D$2:$D$5000,$B$1,Data!$E$2:$E$5000,$B$2,Data!$D$2:$D$5000,$A41,Data!$C$2:$C$5000,E$39)/10^7 -> 3.0921 | F41: =SUMIFS(Data!$M$2:$M$5000,Data!$D$2:$D$5000,$B$1,Data!$E$2:$E$5000,$B$2,Data!$D$2:$D$5000,$A41,Data!$C$2:$C$5000,F$39)/10^7 -> 9.6693
A42: Mar | B42: =IF(E42=0,NA(),E42) -> 4.5562 | C42: =IF(F42=0,NA(),F42) -> 13.079 | E42: =SUMIFS(Data!$M$2:$M$5000,Data!$D$2:$D$5000,$B$1,Data!$E$2:$E$5000,$B$2,Data!$D$2:$D$5000,$A42,Data!$C$2:$C$5000,E$39)/10^7 -> 4.5562 | F42: =SUMIFS(Data!$M$2:$M$5000,Data!$D$2:$D$5000,$B$1,Data!$E$2:$E$5000,$B$2,Data!$D$2:$D$5000,$A42,Data!$C$2:$C$5000,F$39)/10^7 -> 13.079
A43: Apr | B43: =IF(E43=0,NA(),E43) -> 6.7757 | C43: =IF(F43=0,NA(),F43) -> 8.1507 | E43: =SUMIFS(Data!$M$2:$M$5000,Data!$D$2:$D$5000,$B$1,Data!$E$2:$E$5000,$B$2,Data!$D$2:$D$5000,$A43,Data!$C$2:$C$5000,E$39)/10^7 -> 6.7757 | F43: =SUMIFS(Data!$M$2:$M$5000,Data!$D$2:$D$5000,$B$1,Data!$E$2:$E$5000,$B$2,Data!$D$2:$D$5000,$A43,Data!$C$2:$C$5000,F$39)/10^7 -> 8.1507
A44: May | B44: =IF(E44=0,NA(),E44) -> 6.3504 | C44: =IF(F44=0,NA(),F44) -> 5.522 | E44: =SUMIFS(Data!$M$2:$M$5000,Data!$D$2:$D$5000,$B$1,Data!$E$2:$E$5000,$B$2,Data!$D$2:$D$5000,$A44,Data!$C$2:$C$5000,E$39)/10^7 -> 6.3504 | F44: =SUMIFS(Data!$M$2:$M$5000,Data!$D$2:$D$5000,$B$1,Data!$E$2:$E$5000,$B$2,Data!$D$2:$D$5000,$A44,Data!$C$2:$C$5000,F$39)/10^7 -> 5.522
A45: Jun | B45: =IF(E45=0,NA(),E45) -> 3.8131 | C45: =IF(F45=0,NA(),F45) -> 8.8917 | E45: =SUMIFS(Data!$M$2:$M$5000,Data!$D$2:$D$5000,$B$1,Data!$E$2:$E$5000,$B$2,Data!$D$2:$D$5000,$A45,Data!$C$2:$C$5000,E$39)/10^7 -> 3.8131 | F45: =SUMIFS(Data!$M$2:$M$5000,Data!$D$2:$D$5000,$B$1,Data!$E$2:$E$5000,$B$2,Data!$D$2:$D$5000,$A45,Data!$C$2:$C$5000,F$39)/10^7 -> 8.8917
A46: Jul | B46: =IF(E46=0,NA(),E46) -> 5.2811 | C46: =IF(F46=0,NA(),F46) -> 10.4754 | E46: =SUMIFS(Data!$M$2:$M$5000,Data!$D$2:$D$5000,$B$1,Data!$E$2:$E$5000,$B$2,Data!$D$2:$D$5000,$A46,Data!$C$2:$C$5000,E$39)/10^7 -> 5.2811 | F46: =SUMIFS(Data!$M$2:$M$5000,Data!$D$2:$D$5000,$B$1,Data!$E$2:$E$5000,$B$2,Data!$D$2:$D$5000,$A46,Data!$C$2:$C$5000,F$39)/10^7 -> 10.4754
A47: Aug | B47: =IF(E47=0,NA(),E47) -> 4.3944 | C47: =IF(F47=0,NA(),F47) -> 11.1731 | E47: =SUMIFS(Data!$M$2:$M$5000,Data!$D$2:$D$5000,$B$1,Data!$E$2:$E$5000,$B$2,Data!$D$2:$D$5000,$A47,Data!$C$2:$C$5000,E$39)/10^7 -> 4.3944 | F47: =SUMIFS(Data!$M$2:$M$5000,Data!$D$2:$D$5000,$B$1,Data!$E$2:$E$5000,$B$2,Data!$D$2:$D$5000,$A47,Data!$C$2:$C$5000,F$39)/10^7 -> 11.1731
...

Sheet Dashboard
D1: Kia Motors Sales Dashboard
B5: Total Sales | V5: Month
V6: All
V7: Jan
B8: =pivot_table!$E$1 -> 162.3258 | V8: Feb
V9: Mar
V10: Apr
V11: May
B12: Total Profit | V12: Jun
V13: Jul
V14: Aug
B15: =pivot_table!$E$2 -> 26.05413 | V15: Sep
V16: Oct
V17: Nov
V18: Dec
B19: Total COGS
V20: Region
V21: All
B22: =pivot_table!$E$3 -> 136.27167 | V22: North
V23: South
V24: East
V25: West
B26: Total Orders
V27: Click the yellow box (▼) in Month or Region to filter every chart. Choose All to reset.
B29: =pivot_table!$E$4 -> 1010
B33: Sample data for the Kia Motors case study (completed orders, Jan 2025 – 24 Oct 2026). Sales, profit and COGS are in ₹ Crore. Replace the Data sheet rows with real data and everything updates.
